<?xml version="1.0"?>
<!--
  Gazebo ROS ackermann drive plugin demo

  Try sending commands:

    ros2 topic pub /demo/cmd_demo geometry_msgs/msg/Twist '{linear: {x: 1.0}, angular: {z: 0.1}}' -1

  Try listening to odometry:

    ros2 topic echo /demo/odom_demo

  Try listening to odometer reading(linear distance convered):

    ros2 topic echo /demo/distance_demo

  Try listening to TF:

    ros2 run tf2_ros tf2_echo odom_demo chassis

    and other links
-->
<sdf version="1.6">
  <world name="default">
    <include>
      <uri>model://sun</uri>
    </include>

    <include>
      <uri>model://ground_plane</uri>
    </include>

    <model name="ngeeann_av">
      <pose>0 0 0.0 0 0 0</pose>

      <link name='base_link'/>

      <joint name='chassis_link_joint' type='fixed'>
        <pose>0.0 0.0 0.0 0 0 0</pose>
        <parent>base_link</parent>
        <child>chassis_link</child>
      </joint>

      <joint name="hokuyo_joint" type="fixed">
        <parent>base_link</parent>
        <child>hokuyo_link</child>
        <pose>0 0 0 0 0 0</pose>
        <axis>
          <xyz>0 0 1</xyz>
        </axis>
      </joint>

      <link name="hokuyo_link">
        <sensor name="head_hokuyo_sensor" type="ray">
          <always_on>true</always_on>
          <visualize>true</visualize>
          <pose relative_to='base_link'>0 2.34 0.72 0 0 1.5708</pose>
          <update_rate>40</update_rate>
          <ray>
            <scan>
              <horizontal>
                <samples>720</samples>
                <resolution>1.000000</resolution>
                <min_angle>-1.570796</min_angle>
                <max_angle>1.570796</max_angle>
              </horizontal>
            </scan>
            <range>
              <min>0.120000</min>
              <max>30.0</max>
              <resolution>0.010</resolution>
            </range>
            <noise>
              <type>gaussian</type>
              <mean>0.0</mean>
              <stddev>0.01</stddev>
            </noise>
          </ray>
          <plugin name="gazebo_ros_head_hokuyo_controller" filename="libgazebo_ros_ray_sensor.so">
            <ros>
              <remapping>~/out:=scan</remapping>
            </ros>
            <output_type>sensor_msgs/LaserScan</output_type>
            <frame_name>hokuyo_link</frame_name>
          </plugin>
        </sensor>
      </link>

      <link name='chassis_link'>
        <inertial>
          <pose>1e-06 0.07307 0.65096 0 -0 0</pose>
          <mass>1580</mass>
          <inertia>
            <ixx>1997.86</ixx>
            <ixy>-3e-05</ixy>
            <ixz>-1e-06</ixz>
            <iyy>442.769</iyy>
            <iyz>62.5206</iyz>
            <izz>2238.05</izz>
          </inertia>
        </inertial>
        <collision name='chassis_link_fixed_joint_lump__chassis_link_collision'>
          <pose>0 0 0.46936 0 -0 0</pose>
          <geometry>
            <mesh>
              <scale>0.001 0.001 0.001</scale>
              <uri>model://ngeeann_av/meshes/chassis_link.stl</uri>
            </mesh>
          </geometry>
          <surface>
            <contact>
              <ode/>
            </contact>
            <friction>
              <ode>
                <mu>0.2</mu>
                <mu2>0.2</mu2>
              </ode>
            </friction>
          </surface>
        </collision>
        <collision name='chassis_link_fixed_joint_lump__spoiler_link_collision_1'>
          <pose>0 0.05 0.41936 1.5708 -0 3.14159</pose>
          <geometry>
            <mesh>
              <scale>0.001 0.001 0.001</scale>
              <uri>model://ngeeann_av/meshes/spoiler.stl</uri>
            </mesh>
          </geometry>
          <surface>
            <contact>
              <ode/>
            </contact>
            <friction>
              <ode>
                <mu>0.2</mu>
                <mu2>0.2</mu2>
              </ode>
            </friction>
          </surface>
        </collision>
        <visual name='chassis_link_fixed_joint_lump__chassis_link_visual'>
          <pose>0 0 0.46936 0 -0 0</pose>
          <geometry>
            <mesh>
              <scale>0.001 0.001 0.001</scale>
              <uri>model://ngeeann_av/meshes/chassis_link.stl</uri>
            </mesh>
          </geometry>
        </visual>
        <visual name='chassis_link_fixed_joint_lump__spoiler_link_visual_1'>
          <pose>0 0.05 0.41936 1.5708 -0 3.14159</pose>
          <geometry>
            <mesh>
              <scale>0.001 0.001 0.001</scale>
              <uri>model://ngeeann_av/meshes/spoiler.stl</uri>
            </mesh>
          </geometry>
        </visual>
        <!-- <velocity_decay/> -->
        <!--  <gravity>1</gravity> -->
        <!--  <gravity>1</gravity> -->
        <!-- <velocity_decay/> -->
        <self_collide>1</self_collide>
        <!--  <gravity>1</gravity> -->
      </link>
      
      <joint name='bl_axle' type='revolute'>
        <pose relative_to='chassis_link'>-0.875 -1.01364 0.324997 0 -0 0</pose>
        <parent>chassis_link</parent>
        <child>bl_1</child>
        <axis>
          <xyz>-1 0 0</xyz>
          <dynamics>
            <friction>12.031606150200002</friction>
          </dynamics>
        </axis>
      </joint>
      <link name='bl_1'>
        <pose relative_to='bl_axle'>0 0 0 0 -0 0</pose>
        <inertial>
          <pose>-0.0377 0 -0 0 -0 0</pose>
          <mass>24.5</mass>
          <inertia>
            <ixx>1.84514</ixx>
            <ixy>0</ixy>
            <ixz>0</ixz>
            <iyy>1.04961</iyy>
            <iyz>0</iyz>
            <izz>1.04961</izz>
          </inertia>
        </inertial>
        <collision name='bl_1_collision'>
          <pose relative_to='bl_axle'>0 0 0 0 1.5708 0</pose>
          <geometry>
            <cylinder>
              <radius>.3425</radius>
              <length>.22</length>
            </cylinder>
          </geometry>
          <surface>
            <contact>
              <ode/>
            </contact>
            <friction>
              <ode>
                <mu>1.7</mu>
                <mu2>1.7</mu2>
              </ode>
            </friction>
          </surface>
        </collision>
        <visual name='bl_1_visual'>
          <pose>0.875 1.0136 0.1444 0 -0 0</pose>
          <geometry>
            <mesh>
              <scale>0.001 0.001 0.001</scale>
              <uri>model://ngeeann_av/meshes/bl_1.stl</uri>
            </mesh>
          </geometry>
        </visual>
        <!--  <gravity>1</gravity> -->
        <!-- <velocity_decay/> -->
        <self_collide>1</self_collide>
      </link>
      <joint name='br_axle' type='revolute'>
        <pose relative_to='chassis_link'>0.875 -1.01364 0.324997 0 -0 0</pose>
        <parent>chassis_link</parent>
        <child>br_1</child>
        <axis>
          <xyz>-1 0 0</xyz>
          <dynamics>
            <friction>12.031606150200002</friction>
          </dynamics>
        </axis>
      </joint>
      <link name='br_1'>
        <pose relative_to='br_axle'>0 0 0 0 -0 0</pose>
        <inertial>
          <pose>-0.0377 0 -0 0 -0 0</pose>
          <mass>24.5</mass>
          <inertia>
            <ixx>1.84514</ixx>
            <ixy>0</ixy>
            <ixz>0</ixz>
            <iyy>1.04961</iyy>
            <iyz>0</iyz>
            <izz>1.04961</izz>
          </inertia>
        </inertial>
        <collision name='br_1_collision'>
          <pose relative_to='br_axle'>0 0 0 0 1.5708 0</pose>
          <geometry>
            <cylinder>
              <radius>.3425</radius>
              <length>.22</length>
            </cylinder>
          </geometry>
          <surface>
            <contact>
              <ode/>
            </contact>
            <friction>
              <ode>
                <mu>1.7</mu>
                <mu2>1.7</mu2>
              </ode>
            </friction>
          </surface>
        </collision>
        <visual name='br_1_visual'>
          <pose>-0.875 1.0136 0.1444 0 -0 0</pose>
          <geometry>
            <mesh>
              <scale>0.001 0.001 0.001</scale>
              <uri>model://ngeeann_av/meshes/br_1.stl</uri>
            </mesh>
          </geometry>
        </visual>
        <!--  <gravity>1</gravity> -->
        <!-- <velocity_decay/> -->
        <self_collide>1</self_collide>
      </link>
      <joint name='l_steer' type='revolute'>
        <pose relative_to='chassis_link'>-0.825 1.51736 0.324997 0 -0 0</pose>
        <parent>chassis_link</parent>
        <child>l_steer_1</child>
        <axis>
          <xyz>0 0 1</xyz>
          <limit>
            <lower>-0.95</lower>
            <upper>0.95</upper>
          </limit>
          <dynamics>
            <friction>18.0474092253</friction>
          </dynamics>
        </axis>
      </joint>
      <link name='l_steer_1'>
        <pose relative_to='l_steer'>0 0 0 0 -0 0</pose>
        <inertial>
          <pose>0.003381 0 0.02162 0 -0 0</pose>
          <mass>1</mass>
          <inertia>
            <ixx>1</ixx>
            <ixy>0</ixy>
            <ixz>0</ixz>
            <iyy>1</iyy>
            <iyz>0</iyz>
            <izz>1</izz>
          </inertia>
        </inertial>
        <!--  <gravity>1</gravity> -->
        <!-- <velocity_decay/> -->
        <self_collide>1</self_collide>
      </link>

      <joint name='fl_axle' type='revolute'>
        <pose relative_to='l_steer_1'>-0.05 0 0 0 -0 0</pose>
        <parent>l_steer_1</parent>
        <child>fl_1</child>
        <axis>
          <xyz>-1 0 0</xyz>
          <dynamics>
            <friction>12.031606150200002</friction>
          </dynamics>
        </axis>
      </joint>
      <link name='fl_1'>
        <pose relative_to='fl_axle'>0 0 0 0 -0 0</pose>
        <inertial>
          <pose>-0.0377 0 -0 0 -0 0</pose>
          <mass>24.5</mass>
          <inertia>
            <ixx>1.84514</ixx>
            <ixy>0</ixy>
            <ixz>0</ixz>
            <iyy>1.04961</iyy>
            <iyz>0</iyz>
            <izz>1.04961</izz>
          </inertia>
        </inertial>
        <collision name='fl_1_collision'>
          <pose>0.875 -1.5174 0.1444 0 -0 0</pose>
          <geometry>
            <mesh>
              <scale>0.001 0.001 0.001</scale>
              <uri>model://ngeeann_av/meshes/fl_1.stl</uri>
            </mesh>
          </geometry>
          <surface>
            <contact>
              <ode/>
            </contact>
            <friction>
              <ode>
                <mu>1.1</mu>
                <mu2>1.1</mu2>
              </ode>
            </friction>
          </surface>
        </collision>
        <visual name='fl_1_visual'>
          <pose>0.875 -1.5174 0.1444 0 -0 0</pose>
          <geometry>
            <mesh>
              <scale>0.001 0.001 0.001</scale>
              <uri>model://ngeeann_av/meshes/fl_1.stl</uri>
            </mesh>
          </geometry>
        </visual>
        <!--  <gravity>1</gravity> -->
        <!-- <velocity_decay/> -->
        <self_collide>1</self_collide>
      </link>
      <joint name='r_steer' type='revolute'>
        <pose relative_to='chassis_link'>0.825 1.51736 0.324997 0 -0 0</pose>
        <parent>chassis_link</parent>
        <child>r_steer_1</child>
        <axis>
          <xyz>0 0 1</xyz>
          <limit>
            <lower>-0.95</lower>
            <upper>0.95</upper>
          </limit>
          <dynamics>
            <damping>0.01</damping>
            <friction>18.0474092253</friction>
          </dynamics>
        </axis>
      </joint>
      <link name='r_steer_1'>
        <pose relative_to='r_steer'>0 0 0 0 -0 0</pose>
        <inertial>
          <pose>0.003381 0 0.02162 0 -0 0</pose>
          <mass>1</mass>
          <inertia>
            <ixx>1</ixx>
            <ixy>0</ixy>
            <ixz>0</ixz>
            <iyy>1</iyy>
            <iyz>0</iyz>
            <izz>1</izz>
          </inertia>
        </inertial>
        <!--  <gravity>1</gravity> -->
        <!-- <velocity_decay/> -->
        <self_collide>1</self_collide>
      </link>
      <joint name='fr_axle' type='revolute'>
        <pose relative_to='r_steer_1'>0.05 0 0 0 -0 0</pose>
        <parent>r_steer_1</parent>
        <child>fr_1</child>
        <axis>
          <xyz>-1 0 0</xyz>
          <dynamics>
            <friction>12.031606150200002</friction>
          </dynamics>
        </axis>
      </joint>
      <link name='fr_1'>
        <pose relative_to='fr_axle'>0 0 0 0 -0 0</pose>
        <inertial>
          <pose>-0.0377 0 -0 0 -0 0</pose>
          <mass>24.5</mass>
          <inertia>
            <ixx>1.84514</ixx>
            <ixy>0</ixy>
            <ixz>0</ixz>
            <iyy>1.04961</iyy>
            <iyz>0</iyz>
            <izz>1.04961</izz>
          </inertia>
        </inertial>
        <collision name='fr_1_collision'>
          <pose>-0.875 -1.5174 0.1444 0 -0 0</pose>
          <geometry>
            <mesh>
              <scale>0.001 0.001 0.001</scale>
              <uri>model://ngeeann_av/meshes/fr_1.stl</uri>
            </mesh>
          </geometry>
          <surface>
            <contact>
              <ode/>
            </contact>
            <friction>
              <ode>
                <mu>1.7</mu>
                <mu2>1.7</mu2>
              </ode>
            </friction>
          </surface>
        </collision>
        <visual name='fr_1_visual'>
          <pose>-0.875 -1.5174 0.1444 0 -0 0</pose>
          <geometry>
            <mesh>
              <scale>0.001 0.001 0.001</scale>
              <uri>model://ngeeann_av/meshes/fr_1.stl</uri>
            </mesh>
          </geometry>
        </visual>
        <!--  <gravity>1</gravity> -->
        <!-- <velocity_decay/> -->
        <self_collide>1</self_collide>
      </link>

      <link name="steering_wheel"/>

      <joint name="steering_joint" type="revolute">
        <pose>-0.002 0 0 0 0 0</pose>
        <parent>chassis_link</parent>
        <child>steering_wheel</child>
        <axis>
          <xyz>-0.964118 0.000768 0.265556</xyz>
          <limit>
            <lower>-100</lower>
            <upper>100</upper>
          </limit>
          <dynamics>
            <damping>1.0</damping>
          </dynamics>
          <use_parent_model_frame>true</use_parent_model_frame>
        </axis>
        <physics>
          <ode>
            <cfm_damping>1</cfm_damping>
          </ode>
        </physics>
      </joint>

      <plugin name='ackermann_drive' filename='libgazebo_ros_ackermann_drive.so'>

        <ros>
          <namespace>ngeeann_av</namespace>
          <remapping>cmd_vel:=cmd_vel</remapping>
          <remapping>odom:=odom</remapping>
          <remapping>distance:=distance</remapping>
        </ros>

        <update_rate>100.0</update_rate>

        <!-- wheels -->
        <front_left_joint>fl_axle</front_left_joint>
        <front_right_joint>fr_axle</front_right_joint>
        <rear_left_joint>bl_axle</rear_left_joint>
        <rear_right_joint>br_axle</rear_right_joint>
        <left_steering_joint>l_steer</left_steering_joint>
        <right_steering_joint>r_steer</right_steering_joint>
        <steering_wheel_joint>steering_joint</steering_wheel_joint>


        <!-- Max absolute steer angle for tyre in radians-->
        <!-- Any cmd_vel angular z greater than this would be capped -->
        <max_steer>0.85</max_steer>

        <!-- Max absolute steering angle of steering wheel -->
                <!-- Max absolute steering angle of steering wheel -->
        <max_steering_angle>7.85</max_steering_angle>

        <!-- Max absolute linear speed in m/s -->
        <max_speed>20</max_speed>

        <!-- PID tuning -->
        <left_steering_pid_gain>4000 0 1</left_steering_pid_gain>
        <left_steering_i_range>0 0</left_steering_i_range>
        <right_steering_pid_gain>4000 0 1</right_steering_pid_gain>
        <right_steering_i_range>0 0</right_steering_i_range>
        <linear_velocity_pid_gain>4000 0 1</linear_velocity_pid_gain>
        <linear_velocity_i_range>0 0</linear_velocity_i_range>

        <!-- output -->
        <publish_odom>true</publish_odom>
        <publish_odom_tf>true</publish_odom_tf>
        <publish_wheel_tf>true</publish_wheel_tf>
        <publish_distance>true</publish_distance>

        <odometry_frame>odom</odometry_frame>
        <robot_base_frame>base_link</robot_base_frame>

      </plugin>
  
    </model>

    <model name='testmap'>
      <pose>6.27388 16.837 0 0 -0 0</pose>
      <link name='Wall_0'>
        <collision name='Wall_0_Collision'>
          <geometry>
            <box>
              <size>9.5 0.15 2.5</size>
            </box>
          </geometry>
          <pose>0 0 1.25 0 -0 0</pose>
        </collision>
        <visual name='Wall_0_Visual'>
          <pose>0 0 1.25 0 -0 0</pose>
          <geometry>
            <box>
              <size>9.5 0.15 2.5</size>
            </box>
          </geometry>
          <material>
            <script>
              <uri>file://media/materials/scripts/gazebo.material</uri>
              <name>Gazebo/Grey</name>
            </script>
            <ambient>1 1 1 1</ambient>
          </material>
          <meta>
            <layer>0</layer>
          </meta>
        </visual>
        <pose>-14.25 -18.25 0 0 -0 3.14159</pose>
      </link>
      <link name='Wall_1'>
        <collision name='Wall_1_Collision'>
          <geometry>
            <box>
              <size>10.5 0.15 2.5</size>
            </box>
          </geometry>
          <pose>0 0 1.25 0 -0 0</pose>
        </collision>
        <visual name='Wall_1_Visual'>
          <pose>0 0 1.25 0 -0 0</pose>
          <geometry>
            <box>
              <size>10.5 0.15 2.5</size>
            </box>
          </geometry>
          <material>
            <script>
              <uri>file://media/materials/scripts/gazebo.material</uri>
              <name>Gazebo/Grey</name>
            </script>
            <ambient>1 1 1 1</ambient>
          </material>
          <meta>
            <layer>0</layer>
          </meta>
        </visual>
        <pose>-18.925 -13.075 0 0 -0 1.5708</pose>
      </link>
      <link name='Wall_10'>
        <collision name='Wall_10_Collision'>
          <geometry>
            <box>
              <size>63.75 0.15 2.5</size>
            </box>
          </geometry>
          <pose>0 0 1.25 0 -0 0</pose>
        </collision>
        <visual name='Wall_10_Visual'>
          <pose>0 0 1.25 0 -0 0</pose>
          <geometry>
            <box>
              <size>63.75 0.15 2.5</size>
            </box>
          </geometry>
          <material>
            <script>
              <uri>file://media/materials/scripts/gazebo.material</uri>
              <name>Gazebo/Grey</name>
            </script>
            <ambient>1 1 1 1</ambient>
          </material>
          <meta>
            <layer>0</layer>
          </meta>
        </visual>
        <pose>-86.425 -1e-06 0 0 -0 1.5708</pose>
      </link>
      <link name='Wall_11'>
        <collision name='Wall_11_Collision'>
          <geometry>
            <box>
              <size>47.5 0.15 2.5</size>
            </box>
          </geometry>
          <pose>0 0 1.25 0 -0 0</pose>
        </collision>
        <visual name='Wall_11_Visual'>
          <pose>0 0 1.25 0 -0 0</pose>
          <geometry>
            <box>
              <size>47.5 0.15 2.5</size>
            </box>
          </geometry>
          <material>
            <script>
              <uri>file://media/materials/scripts/gazebo.material</uri>
              <name>Gazebo/Grey</name>
            </script>
            <ambient>1 1 1 1</ambient>
          </material>
          <meta>
            <layer>0</layer>
          </meta>
        </visual>
        <pose>-62.75 31.8 0 0 -0 0</pose>
      </link>
      <link name='Wall_12'>
        <collision name='Wall_12_Collision'>
          <geometry>
            <box>
              <size>29.75 0.15 2.5</size>
            </box>
          </geometry>
          <pose>0 0 1.25 0 -0 0</pose>
        </collision>
        <visual name='Wall_12_Visual'>
          <pose>0 0 1.25 0 -0 0</pose>
          <geometry>
            <box>
              <size>29.75 0.15 2.5</size>
            </box>
          </geometry>
          <material>
            <script>
              <uri>file://media/materials/scripts/gazebo.material</uri>
              <name>Gazebo/Grey</name>
            </script>
            <ambient>1 1 1 1</ambient>
          </material>
          <meta>
            <layer>0</layer>
          </meta>
        </visual>
        <pose>-39.075 17 0 0 -0 -1.5708</pose>
      </link>
      <link name='Wall_13'>
        <collision name='Wall_13_Collision'>
          <geometry>
            <box>
              <size>16 0.15 2.5</size>
            </box>
          </geometry>
          <pose>0 0 1.25 0 -0 0</pose>
        </collision>
        <visual name='Wall_13_Visual'>
          <pose>0 0 1.25 0 -0 0</pose>
          <geometry>
            <box>
              <size>16 0.15 2.5</size>
            </box>
          </geometry>
          <material>
            <script>
              <uri>file://media/materials/scripts/gazebo.material</uri>
              <name>Gazebo/Grey</name>
            </script>
            <ambient>1 1 1 1</ambient>
          </material>
          <meta>
            <layer>0</layer>
          </meta>
        </visual>
        <pose>-31.15 2.2 0 0 -0 0</pose>
      </link>
      <link name='Wall_14'>
        <collision name='Wall_14_Collision'>
          <geometry>
            <box>
              <size>20.5 0.15 2.5</size>
            </box>
          </geometry>
          <pose>0 0 1.25 0 -0 0</pose>
        </collision>
        <visual name='Wall_14_Visual'>
          <pose>0 0 1.25 0 -0 0</pose>
          <geometry>
            <box>
              <size>20.5 0.15 2.5</size>
            </box>
          </geometry>
          <material>
            <script>
              <uri>file://media/materials/scripts/gazebo.material</uri>
              <name>Gazebo/Grey</name>
            </script>
            <ambient>1 1 1 1</ambient>
          </material>
          <meta>
            <layer>0</layer>
          </meta>
        </visual>
        <pose>-23.225 -7.975 0 0 -0 -1.5708</pose>
      </link>
      <link name='Wall_15'>
        <collision name='Wall_15_Collision'>
          <geometry>
            <box>
              <size>4.5 0.15 2.5</size>
            </box>
          </geometry>
          <pose>0 0 1.25 0 -0 0</pose>
        </collision>
        <visual name='Wall_15_Visual'>
          <pose>0 0 1.25 0 -0 0</pose>
          <geometry>
            <box>
              <size>4.5 0.15 2.5</size>
            </box>
          </geometry>
          <material>
            <script>
              <uri>file://media/materials/scripts/gazebo.material</uri>
              <name>Gazebo/Grey</name>
            </script>
            <ambient>1 1 1 1</ambient>
          </material>
          <meta>
            <layer>0</layer>
          </meta>
        </visual>
        <pose>-21.05 -18.15 0 0 -0 0</pose>
      </link>
      <link name='Wall_17'>
        <collision name='Wall_17_Collision'>
          <geometry>
            <box>
              <size>31 0.15 2.5</size>
            </box>
          </geometry>
          <pose>0 0 1.25 0 -0 0</pose>
        </collision>
        <visual name='Wall_17_Visual'>
          <pose>0 0 1.25 0 -0 0</pose>
          <geometry>
            <box>
              <size>31 0.15 2.5</size>
            </box>
          </geometry>
          <material>
            <script>
              <uri>file://media/materials/scripts/gazebo.material</uri>
              <name>Gazebo/Grey</name>
            </script>
            <ambient>1 1 1 1</ambient>
          </material>
          <meta>
            <layer>0</layer>
          </meta>
        </visual>
        <pose>38.1942 16.28 0 0 -0 -1.5708</pose>
      </link>
      <link name='Wall_18'>
        <collision name='Wall_18_Collision'>
          <geometry>
            <box>
              <size>27.5 0.15 2.5</size>
            </box>
          </geometry>
          <pose>0 0 1.25 0 -0 0</pose>
        </collision>
        <visual name='Wall_18_Visual'>
          <pose>0 0 1.25 0 -0 0</pose>
          <geometry>
            <box>
              <size>27.5 0.15 2.5</size>
            </box>
          </geometry>
          <material>
            <script>
              <uri>file://media/materials/scripts/gazebo.material</uri>
              <name>Gazebo/Grey</name>
            </script>
            <ambient>1 1 1 1</ambient>
          </material>
          <meta>
            <layer>0</layer>
          </meta>
        </visual>
        <pose>51.8692 0.85498 0 0 -0 0</pose>
      </link>
      <link name='Wall_19'>
        <collision name='Wall_19_Collision'>
          <geometry>
            <box>
              <size>9.5 0.15 2.5</size>
            </box>
          </geometry>
          <pose>0 0 1.25 0 -0 0</pose>
        </collision>
        <visual name='Wall_19_Visual'>
          <pose>0 0 1.25 0 -0 0</pose>
          <geometry>
            <box>
              <size>9.5 0.15 2.5</size>
            </box>
          </geometry>
          <material>
            <script>
              <uri>file://media/materials/scripts/gazebo.material</uri>
              <name>Gazebo/Grey</name>
            </script>
            <ambient>1 1 1 1</ambient>
          </material>
          <meta>
            <layer>0</layer>
          </meta>
        </visual>
        <pose>65.5442 5.52998 0 0 -0 1.5708</pose>
      </link>
      <link name='Wall_2'>
        <collision name='Wall_2_Collision'>
          <geometry>
            <box>
              <size>2.75 0.15 2.5</size>
            </box>
          </geometry>
          <pose>0 0 1.25 0 -0 0</pose>
        </collision>
        <visual name='Wall_2_Visual'>
          <pose>0 0 1.25 0 -0 0</pose>
          <geometry>
            <box>
              <size>2.75 0.15 2.5</size>
            </box>
          </geometry>
          <material>
            <script>
              <uri>file://media/materials/scripts/gazebo.material</uri>
              <name>Gazebo/Grey</name>
            </script>
            <ambient>1 1 1 1</ambient>
          </material>
          <meta>
            <layer>0</layer>
          </meta>
        </visual>
        <pose>-17.625 -7.9 0 0 -0 0</pose>
      </link>
      <link name='Wall_21'>
        <collision name='Wall_21_Collision'>
          <geometry>
            <box>
              <size>27.25 0.15 2.5</size>
            </box>
          </geometry>
          <pose>0 0 1.25 0 -0 0</pose>
        </collision>
        <visual name='Wall_21_Visual'>
          <pose>0 0 1.25 0 -0 0</pose>
          <geometry>
            <box>
              <size>27.25 0.15 2.5</size>
            </box>
          </geometry>
          <material>
            <script>
              <uri>file://media/materials/scripts/gazebo.material</uri>
              <name>Gazebo/Grey</name>
            </script>
            <ambient>1 1 1 1</ambient>
          </material>
          <meta>
            <layer>0</layer>
          </meta>
        </visual>
        <pose>-50.5941 1.68965 0 0 -0 -2.61799</pose>
      </link>
      <link name='Wall_23'>
        <collision name='Wall_23_Collision'>
          <geometry>
            <box>
              <size>47 0.15 2.5</size>
            </box>
          </geometry>
          <pose>0 0 1.25 0 -0 0</pose>
        </collision>
        <visual name='Wall_23_Visual'>
          <pose>0 0 1.25 0 -0 0</pose>
          <geometry>
            <box>
              <size>47 0.15 2.5</size>
            </box>
          </geometry>
          <material>
            <script>
              <uri>file://media/materials/scripts/gazebo.material</uri>
              <name>Gazebo/Grey</name>
            </script>
            <ambient>1 1 1 1</ambient>
          </material>
          <meta>
            <layer>0</layer>
          </meta>
        </visual>
        <pose>-9.99019 19.3531 0 0 -0 0</pose>
      </link>
      <link name='Wall_24'>
        <collision name='Wall_24_Collision'>
          <geometry>
            <box>
              <size>22.25 0.15 2.5</size>
            </box>
          </geometry>
          <pose>0 0 1.25 0 -0 0</pose>
        </collision>
        <visual name='Wall_24_Visual'>
          <pose>0 0 1.25 0 -0 0</pose>
          <geometry>
            <box>
              <size>22.25 0.15 2.5</size>
            </box>
          </geometry>
          <material>
            <script>
              <uri>file://media/materials/scripts/gazebo.material</uri>
              <name>Gazebo/Grey</name>
            </script>
            <ambient>1 1 1 1</ambient>
          </material>
          <meta>
            <layer>0</layer>
          </meta>
        </visual>
        <pose>13.4348 8.30311 0 0 -0 -1.5708</pose>
      </link>
      <link name='Wall_4'>
        <collision name='Wall_4_Collision'>
          <geometry>
            <box>
              <size>16.25 0.15 2.5</size>
            </box>
          </geometry>
          <pose>0 0 1.25 0 -0 0</pose>
        </collision>
        <visual name='Wall_4_Visual'>
          <pose>0 0 1.25 0 -0 0</pose>
          <geometry>
            <box>
              <size>16.25 0.15 2.5</size>
            </box>
          </geometry>
          <material>
            <script>
              <uri>file://media/materials/scripts/gazebo.material</uri>
              <name>Gazebo/Grey</name>
            </script>
            <ambient>1 1 1 1</ambient>
          </material>
          <meta>
            <layer>0</layer>
          </meta>
        </visual>
        <pose>-16.325 0.149999 0 0 -0 1.5708</pose>
      </link>
      <link name='Wall_5'>
        <collision name='Wall_5_Collision'>
          <geometry>
            <box>
              <size>17 0.15 2.5</size>
            </box>
          </geometry>
          <pose>0 0 1.25 0 -0 0</pose>
        </collision>
        <visual name='Wall_5_Visual'>
          <pose>0 0 1.25 0 -0 0</pose>
          <geometry>
            <box>
              <size>17 0.15 2.5</size>
            </box>
          </geometry>
          <material>
            <script>
              <uri>file://media/materials/scripts/gazebo.material</uri>
              <name>Gazebo/Grey</name>
            </script>
            <ambient>1 1 1 1</ambient>
          </material>
          <meta>
            <layer>0</layer>
          </meta>
        </visual>
        <pose>-24.75 8.2 0 0 -0 3.14159</pose>
      </link>
      <link name='Wall_6'>
        <collision name='Wall_6_Collision'>
          <geometry>
            <box>
              <size>23.5 0.15 2.5</size>
            </box>
          </geometry>
          <pose>0 0 1.25 0 -0 0</pose>
        </collision>
        <visual name='Wall_6_Visual'>
          <pose>0 0 1.25 0 -0 0</pose>
          <geometry>
            <box>
              <size>23.5 0.15 2.5</size>
            </box>
          </geometry>
          <material>
            <script>
              <uri>file://media/materials/scripts/gazebo.material</uri>
              <name>Gazebo/Grey</name>
            </script>
            <ambient>1 1 1 1</ambient>
          </material>
          <meta>
            <layer>0</layer>
          </meta>
        </visual>
        <pose>-33.175 19.875 0 0 -0 1.5708</pose>
      </link>
      <link name='Wall_7'>
        <collision name='Wall_7_Collision'>
          <geometry>
            <box>
              <size>119.75 0.15 2.5</size>
            </box>
          </geometry>
          <pose>0 0 1.25 0 -0 0</pose>
        </collision>
        <visual name='Wall_7_Visual'>
          <pose>0 0 1.25 0 -0 0</pose>
          <geometry>
            <box>
              <size>119.75 0.15 2.5</size>
            </box>
          </geometry>
          <material>
            <script>
              <uri>file://media/materials/scripts/gazebo.material</uri>
              <name>Gazebo/Grey</name>
            </script>
            <ambient>1 1 1 1</ambient>
          </material>
          <meta>
            <layer>0</layer>
          </meta>
        </visual>
        <pose>26.625 31.55 0 0 -0 0</pose>
      </link>
      <link name='Wall_8'>
        <collision name='Wall_8_Collision'>
          <geometry>
            <box>
              <size>63.5 0.15 2.5</size>
            </box>
          </geometry>
          <pose>0 0 1.25 0 -0 0</pose>
        </collision>
        <visual name='Wall_8_Visual'>
          <pose>0 0 1.25 0 -0 0</pose>
          <geometry>
            <box>
              <size>63.5 0.15 2.5</size>
            </box>
          </geometry>
          <material>
            <script>
              <uri>file://media/materials/scripts/gazebo.material</uri>
              <name>Gazebo/Grey</name>
            </script>
            <ambient>1 1 1 1</ambient>
          </material>
          <meta>
            <layer>0</layer>
          </meta>
        </visual>
        <pose>86.425 -0.125001 0 0 -0 -1.5708</pose>
      </link>
      <link name='Wall_9'>
        <collision name='Wall_9_Collision'>
          <geometry>
            <box>
              <size>173 0.15 2.5</size>
            </box>
          </geometry>
          <pose>0 0 1.25 0 -0 0</pose>
        </collision>
        <visual name='Wall_9_Visual'>
          <pose>0 0 1.25 0 -0 0</pose>
          <geometry>
            <box>
              <size>173 0.15 2.5</size>
            </box>
          </geometry>
          <material>
            <script>
              <uri>file://media/materials/scripts/gazebo.material</uri>
              <name>Gazebo/Grey</name>
            </script>
            <ambient>1 1 1 1</ambient>
          </material>
          <meta>
            <layer>0</layer>
          </meta>
        </visual>
        <pose>-2e-06 -31.8 0 0 -0 3.14159</pose>
      </link>
      <static>1</static>
    </model>

  </world>
</sdf>
